Workbook

Sheet 요약
A1: WBS — 주식 AI 리서치
A2: 시장 현황·종목 차트·기술적 신호·뉴스를 한 화면에서 보고, 멀티 에이전트 AI가 판단 근거와 함께 의견을 제시하는 주식 리서치 보조 서비스
A3: 2026-08-21 기준 · 상세 내역은 [WBS] 시트, 남은 작업 순서는 [로드맵] 시트 · 할 일의 정본은 docs/남은-할-일.md
A5: 영역 | B5: 완료 | C5: 진행 중 | D5: 예정 | E5: 보류 | F5: 계 | G5: 진행률
A6: 기획 | B6: =COUNTIFS(WBS!$B:$B,$A6,WBS!$E:$E,B$5) -> 3 | C6: =COUNTIFS(WBS!$B:$B,$A6,WBS!$E:$E,C$5) -> 0 | D6: =COUNTIFS(WBS!$B:$B,$A6,WBS!$E:$E,D$5) -> 0 | E6: =COUNTIFS(WBS!$B:$B,$A6,WBS!$E:$E,E$5) -> 1 | F6: =SUM(B6:E6) -> 4 | G6: =(B6+0.5*C6)/F6 -> 0.75
A7: 백엔드 | B7: =COUNTIFS(WBS!$B:$B,$A7,WBS!$E:$E,B$5) -> 5 | C7: =COUNTIFS(WBS!$B:$B,$A7,WBS!$E:$E,C$5) -> 1 | D7: =COUNTIFS(WBS!$B:$B,$A7,WBS!$E:$E,D$5) -> 0 | E7: =COUNTIFS(WBS!$B:$B,$A7,WBS!$E:$E,E$5) -> 0 | F7: =SUM(B7:E7) -> 6 | G7: =(B7+0.5*C7)/F7 -> 0.91666667
A8: AI 파이프라인 | B8: =COUNTIFS(WBS!$B:$B,$A8,WBS!$E:$E,B$5) -> 1 | C8: =COUNTIFS(WBS!$B:$B,$A8,WBS!$E:$E,C$5) -> 2 | D8: =COUNTIFS(WBS!$B:$B,$A8,WBS!$E:$E,D$5) -> 4 | E8: =COUNTIFS(WBS!$B:$B,$A8,WBS!$E:$E,E$5) -> 0 | F8: =SUM(B8:E8) -> 7 | G8: =(B8+0.5*C8)/F8 -> 0.28571429
A9: 프런트엔드 | B9: =COUNTIFS(WBS!$B:$B,$A9,WBS!$E:$E,B$5) -> 7 | C9: =COUNTIFS(WBS!$B:$B,$A9,WBS!$E:$E,C$5) -> 1 | D9: =COUNTIFS(WBS!$B:$B,$A9,WBS!$E:$E,D$5) -> 1 | E9: =COUNTIFS(WBS!$B:$B,$A9,WBS!$E:$E,E$5) -> 0 | F9: =SUM(B9:E9) -> 9 | G9: =(B9+0.5*C9)/F9 -> 0.83333333
A10: 인증·보안 | B10: =COUNTIFS(WBS!$B:$B,$A10,WBS!$E:$E,B$5) -> 3 | C10: =COUNTIFS(WBS!$B:$B,$A10,WBS!$E:$E,C$5) -> 0 | D10: =COUNTIFS(WBS!$B:$B,$A10,WBS!$E:$E,D$5) -> 2 | E10: =COUNTIFS(WBS!$B:$B,$A10,WBS!$E:$E,E$5) -> 0 | F10: =SUM(B10:E10) -> 5 | G10: =(B10+0.5*C10)/F10 -> 0.6
A11: 품질·CI | B11: =COUNTIFS(WBS!$B:$B,$A11,WBS!$E:$E,B$5) -> 2 | C11: =COUNTIFS(WBS!$B:$B,$A11,WBS!$E:$E,C$5) -> 0 | D11: =COUNTIFS(WBS!$B:$B,$A11,WBS!$E:$E,D$5) -> 2 | E11: =COUNTIFS(WBS!$B:$B,$A11,WBS!$E:$E,E$5) -> 0 | F11: =SUM(B11:E11) -> 4 | G11: =(B11+0.5*C11)/F11 -> 0.5
A12: 운영·배포 | B12: =COUNTIFS(WBS!$B:$B,$A12,WBS!$E:$E,B$5) -> 0 | C12: =COUNTIFS(WBS!$B:$B,$A12,WBS!$E:$E,C$5) -> 2 | D12: =COUNTIFS(WBS!$B:$B,$A12,WBS!$E:$E,D$5) -> 3 | E12: =COUNTIFS(WBS!$B:$B,$A12,WBS!$E:$E,E$5) -> 0 | F12: =SUM(B12:E12) -> 5 | G12: =(B12+0.5*C12)/F12 -> 0.2
A13: 문서화 | B13: =COUNTIFS(WBS!$B:$B,$A13,WBS!$E:$E,B$5) -> 1 | C13: =COUNTIFS(WBS!$B:$B,$A13,WBS!$E:$E,C$5) -> 1 | D13: =COUNTIFS(WBS!$B:$B,$A13,WBS!$E:$E,D$5) -> 1 | E13: =COUNTIFS(WBS!$B:$B,$A13,WBS!$E:$E,E$5) -> 0 | F13: =SUM(B13:E13) -> 3 | G13: =(B13+0.5*C13)/F13 -> 0.5
A14: 전체 | B14: =SUM(B6:B13) -> 22 | C14: =SUM(C6:C13) -> 7 | D14: =SUM(D6:D13) -> 13 | E14: =SUM(E6:E13) -> 1 | F14: =SUM(F6:F13) -> 43 | G14: =(B14+0.5*C14)/F14 -> 0.59302326
A16: 진행률 = (완료 + 진행 중 × 0.5) ÷ 계. 표의 숫자는 [WBS] 시트의 상태 열을 세는 수식이라, 상태를 고치면 함께 바뀐다.
A17: 상태 기준 — 완료: 코드·검증 종료 · 진행 중: 일부 구현/검증 미완 · 예정: 착수 전 · 보류: 의도적으로 미룸.

Sheet WBS
A1: WBS | B1: 영역 | C1: 작업 패키지 | D1: 상세 내용 | E1: 상태 | F1: 관련 항목 | G1: 남은 일 · 비고
A2: 1.1 | B2: 기획 | C2: 제품 기획서 | D2: 사용자 가설·핵심 흐름·API 명세·착수 순서를 담은 초기 제품 기획 (docs/product-plan.md). | E2: 완료 | F2: —
A3: 1.2 | B3: 기획 | C3: 화면 설계서·사업계획서 | D3: 화면설계서·사업계획서 등 발표 자료(pptx 4종)와 설계 문서 화면(/wireframes). | E3: 완료 | F3: —
A4: 1.3 | B4: 기획 | C4: 화면 고도화 기획 | D4: 예비 사용자 피드백 대응 설계 — F-1 관심종목 작업대, F-2 UI 경쟁력 진단 (docs/화면-고도화-기획.md). | E4: 완료 | F4: —
A5: 1.4 | B5: 기획 | C5: 사주 × AI 통합 기획 | D5: 사주를 적합성(suitability) 축으로 쓰는 통합 설계. 기획서는 완성 (docs/saju-integration-plan.md). | E5: 보류 | F5: — | G5: 이번 범위에서 전면 제외하기로 결정
A6: 2.1 | B6: 백엔드 | C6: 데이터 계층 | D6: SQLAlchemy(async) 모델·리포지토리, alembic 마이그레이션 사슬 (baseline 리비전 포함, drift 0). | E6: 완료 | F6: —
A7: 2.2 | B7: 백엔드 | C7: 외부 연동 | D7: yfinance 시세 클라이언트. 429(레이트리밋)를 분류해 후보 루프를 즉시 중단하고 503 반환. | E7: 완료 | F7: —
A8: 2.3 | B8: 백엔드 | C8: 시세·검색·지표 API | D8: markets(overview·movers·screener·calendar), stocks(history·content·fundamentals·suggestions). | E8: 완료 | F8: —
A9: 2.4 | B9: 백엔드 | C9: 관심종목·프로파일 API | D9: watchlist 6개, profile 4개 엔드포인트. | E9: 완료 | F9: —
A10: 2.5 | B10: 백엔드 | C10: 관리자 API | D10: admin 6개 — 회원 관리, 감사로그, batch_runs, 운영 화면(/admin/ops) 데이터. | E10: 완료 | F10: —
A11: 2.6 | B11: 백엔드 | C11: 스냅샷 배치 | D11: 지표 스냅샷을 주기적으로 갱신하는 배치. 실패 시 30분 백오프까지 구현. | E11: 진행 중 | F11: P1-4 | G11: cron 등 실행 주체가 없어 화면 요청이 유일한 트리거 — 스크립트 + 하루 2~3회 실행 필요
A12: 3.1 | B12: AI 파이프라인 | C12: 멀티 에이전트 그래프 | D12: 분석가 에이전트 3인 + 최종 판단 구조(agents·graph). 실제 판단 생성 동작. | E12: 완료 | F12: —
A13: 3.2 | B13: AI 파이프라인 | C13: 하이브리드 검색(RAG) | D13: 벡터 + 키워드 RRF 결합 검색. 벡터 축은 정상 동작. | E13: 진행 중 | F13: P1-13 | G13: 키워드 축이 사실상 0건으로 퇴화 — 질의 방식 보정과 축별 건수 로그 필요
A14: 3.3 | B14: AI 파이프라인 | C14: 인용 검증 | D14: AI 답변의 인용(D번호)이 실제 문서와 맞는지 검증. | E14: 진행 중 | F14: P2-3 | G14: answer만 검사 — 화면에 그려지는 buy_conditions·risk_notes로 확대 필요
A15: 3.4 | B15: AI 파이프라인 | C15: LLM 지출 계량 | D15: 판단 1회당 토큰·비용을 측정하는 계량기. 현재 usage를 읽는 코드 0건. | E15: 예정 | F15: P1-19 | G15: 총량 한도(5.4)의 선행 조건 — 측정이 한도보다 먼저
A16: 3.5 | B16: AI 파이프라인 | C16: 실행 예산·하트비트 | D16: 그래프 전체 실행 시간 예산 강제 + SSE 하트비트로 무음 구간 제거. | E16: 예정 | F16: P1-15 | G16: 현재 LLM 상한 300초뿐, 전체 예산 없음 — 동시 슬롯 점유로 다른 요청 429 유발
A17: 3.6 | B17: AI 파이프라인 | C17: 폴백 캐시 정책 | D17: 비용을 치른 폴백 결과는 캐시하고, 망가진 결과는 연장하지 않는 정책. | E17: 예정 | F17: P1-6
A18: 3.7 | B18: AI 파이프라인 | C18: 프롬프트 격리 | D18: 뉴스·문서 본문 속 문장이 AI를 조종하지 못하게 하는 주입 방어. | E18: 예정 | F18: P1-14 | G18: 인용 규칙에 격리 문구 추가, 2단계 전파 차단
A19: 4.1 | B19: 프런트엔드 | C19: 공통 기반 | D19: 전 화면 서버 컴포넌트, cacheComponents 캐싱, BFF, 폭 토큰(1440px). | E19: 완료 | F19: —
A20: 4.2 | B20: 프런트엔드 | C20: 시장 현황 홈 ( / ) | D20: 지수·등락 상위·오늘의 일정 등 시장 현황 화면. | E20: 완료 | F20: —
A21: 4.3 | B21: 프런트엔드 | C21: 종목 상세 | D21: /stocks/[symbol] — 서버 SVG 차트, 에디토리얼 조판, 투자 지표·밸류에이션. | E21: 완료 | F21: —
A22: 4.4 | B22: 프런트엔드 | C22: AI 투자 판단 화면 | D22: …/advice — Suspense 스트리밍으로 폴링 없이 결과 표시. | E22: 완료 | F22: —
A23: 4.5 | B23: 프런트엔드 | C23: 스크리너 | D23: /stocks/screener — 조건 검색. | E23: 완료 | F23: —
A24: 4.6 | B24: 프런트엔드 | C24: 검색·자동완성(⌘K) | D24: 헤더 검색창 + 커맨드 팔레트, BFF 경유 자동완성. | E24: 진행 중 | F24: P1-17 | G24: 요청 1건이 백엔드를 6회 호출 — 표시명 일괄 조회와 enabled 가드로 축소
A25: 4.7 | B25: 프런트엔드 | C25: 대시보드(작업대) | D25: /dashboard·[code] — 관심종목 목록 + 상세 분할 화면. watchlist와 통합(26-08-18). | E25: 완료 | F25: —
A26: 4.8 | B26: 프런트엔드 | C26: 관리자 화면 | D26: /admin — 회원 관리, 운영(ops) 현황. | E26: 완료 | F26: —
A27: 4.9 | B27: 프런트엔드 | C27: 미해석 화면 정리 | D27: 해석 안 되는 심볼 화면에서 하드코딩 목(mock) 시세가 실서식으로 렌더되는 것 제거. | E27: 예정 | F27: P1-16 | G27: 홈과 같은 SampleFrame 규약으로 편입
A28: 5.1 | B28: 인증·보안 | C28: 로그인 | D28: 이메일+비밀번호(scrypt), 구글 OAuth — JWT 세션(26-08-18). | E28: 완료 | F28: —
A29: 5.2 | B29: 인증·보안 | C29: 가입·인증 메일 | D29: 개발자 모드 한정 /signup·/verify + 관리자 계정 발급. | E29: 완료 | F29: —
A30: 5.3 | B30: 인증·보안 | C30: 관리자 인가 | D30: X-Admin-Key + 감사로그, 프런트 인가 게이트. | E30: 완료 | F30: —
A31: 5.4 | B31: 인증·보안 | C31: AI 판단 입구 인가·총량 한도 | D31: AI 분석 요청 입구(BFF)에 인증과 사용자별 총량 한도를 거는 작업. 현재 무인증·총량 무제한. | E31: 예정 | F31: P0-5 | G31: 남은 유일한 P0. 선행: 3.4 지출 계량 — 측정 없이 정한 한도는 임의값
A32: 5.5 | B32: 인증·보안 | C32: 남용 방지·법적 고지 | D32: 인증 메일 발송 레이트리밋 + 개인정보처리방침·이용약관 화면. | E32: 예정 | F32: P1-20·21
A33: 6.1 | B33: 품질·CI | C33: 백엔드 테스트 | D33: pytest 382개(26-08-11 기준), ruff 린트 — 전부 통과. | E33: 완료 | F33: —
A34: 6.2 | B34: 품질·CI | C34: 프런트 테스트 | D34: 테스트 91개 이상(26-08-18 기준), tsc·eslint·next build — 전부 통과. | E34: 완료 | F34: —
A35: 6.3 | B35: 품질·CI | C35: 테스트 공백 보강 | D35: 인가 함수(adminActorOf 등)와 신규 순수 함수 계층(screener·match·sort)에 테스트 추가. | E35: 예정 | F35: P1-11·P2-21
A36: 6.4 | B36: 품질·CI | C36: CI 파이프라인 | D36: 커밋마다 린트·테스트·빌드를 자동 실행하는 게이트. | E36: 예정 | F36: P1-7 | G36: 선결: 테스트 하네스 DB, ruff 34건, Node 버전 핀, 빌드 시 폰트 네트워크
A37: 7.1 | B37: 운영·배포 | C37: 백엔드 컨테이너 | D37: Dockerfile, compose(migrate 서비스 분리) 구성 완료. | E37: 진행 중 | F37: P1-1 | G37: docker 없는 개발 환경이라 이미지 빌드·기동은 실행 검증 미완
A38: 7.2 | B38: 운영·배포 | C38: 배치 운영(cron) | D38: refresh_snapshots 스크립트 + 하루 2~3회 스케줄 실행. | E38: 예정 | F38: P1-4 | G38: 2.6의 백오프가 먼저 있어야 실패가 증폭되지 않는다
A39: 7.3 | B39: 운영·배포 | C39: 관측·경보 | D39: 배치 결과 기록(batch_runs)과 /admin/ops 표시까지 완료. | E39: 진행 중 | F39: P2-15 | G39: 남은 것: JSON 로그, 외부 알림(메일 등), health/ready 분리
A40: 7.4 | B40: 운영·배포 | C40: 프런트 배포 산출물 | D40: 프런트를 실서비스에 올릴 방식(Dockerfile·standalone·vercel) 결정과 구성. | E40: 예정 | F40: P2-22
...

Sheet 로드맵
A1: 잔여 로드맵
A2: docs/남은-할-일.md의 '이번 주' 순서. 의존 관계가 있는 순서라 앞뒤를 뒤집으면 안 된다.
A4: 단계 | B4: 상태 | C4: 할 일 | D4: 대상 WBS | E4: 왜 이 순서인가
A5: 1 | B5: 완료 | C5: 워킹 트리·마이그레이션 커밋 + 환경 템플릿 정리 | D5: — | E5: 2026-08-11 완료
A6: 2 | B6: 완료 | C6: 입력 검증 한 묶음 — 종목코드 검증, 심볼 형태 게이트, 검색 상한 | D6: — | E6: 2026-08-11 완료
A7: 3 | B7: 완료 | C7: 상류 실패 정직화 — 429→503 분류, 배치 백오프, 배치 결과 기록 | D7: — | E7: 2026-08-11 완료
A8: 4 | B8: 완료 | C8: 스키마 단일 출처 — baseline 리비전, create_all 차단, compose migrate | D8: — | E8: 2026-08-11 완료
A9: 5 | B9: 예정 | C9: AI 입구 — 지출 계량 → 입구 인가·총량 한도 → 실행 예산·하트비트 → 폴백 캐시 | D9: 3.4 → 5.4 → 3.5 → 3.6 | E9: 계량 없이 정한 한도는 임의값이다. 내부 순서 고정.
A10: 6 | B10: 예정 | C10: 배치 운영 — cron 하루 2~3회 자동 실행 | D10: 7.2 | E10: 백오프(2.6)가 먼저 있어야 실패가 증폭되지 않는다
A11: 7 | B11: 예정 | C11: CI 게이트 — 커밋마다 자동 검사 | D11: 6.4 | E11: 앞 단계가 만든 회귀를 기계로 고정한다
A12: 8 | B12: 예정 | C12: 문서를 사실로 — README·명세·오류 봉투 통일·인가 테스트 | D12: 8.2 · 8.3 · 6.3 | E12: 앞 단계가 사실을 바꿔 놓으므로 마지막에 한 번만 맞춘다
A14: 순서와 무관하게 값싼 것부터: P2-3 · P2-18 · P2-11 · P2-12 · P1-18
A15: 그 외 백로그(P2 26건 · P3 3건)의 정본은 docs/남은-할-일.md
